<?xml version="1.0"?>
<robot name="navigation_sim" xmlns:xacro="http://www.ros.org/wiki/xacro">

  <!-- ── Materials ── -->
  <material name="blue"><color rgba="0.2 0.4 0.8 1"/></material>
  <material name="black"><color rgba="0.1 0.1 0.1 1"/></material>
  <material name="gray"><color rgba="0.6 0.6 0.6 1"/></material>

  <!-- ── Base link ── -->
  <link name="base_link">
    <visual>
      <geometry><box size="0.4 0.3 0.1"/></geometry>
      <material name="blue"/>
    </visual>
    <collision>
      <geometry><box size="0.4 0.3 0.1"/></geometry>
    </collision>
    <inertial>
      <mass value="5.0"/>
      <inertia ixx="0.05" ixy="0" ixz="0" iyy="0.06" iyz="0" izz="0.09"/>
    </inertial>
  </link>

  <!-- ── Wheel macro ── -->
  <xacro:macro name="wheel" params="name x_reflect y_reflect">
    <link name="${name}_wheel">
      <visual>
        <geometry><cylinder radius="0.08" length="0.04"/></geometry>
        <material name="black"/>
      </visual>
      <collision>
        <geometry><cylinder radius="0.08" length="0.04"/></geometry>
      </collision>
      <inertial>
        <mass value="0.5"/>
        <inertia ixx="0.001" ixy="0" ixz="0" iyy="0.001" iyz="0" izz="0.001"/>
      </inertial>
    </link>
    <joint name="${name}_wheel_joint" type="continuous">
      <parent link="base_link"/>
      <child link="${name}_wheel"/>
      <origin xyz="${x_reflect * 0.0} ${y_reflect * 0.17} -0.01"
              rpy="${pi/2} 0 0"/>
      <axis xyz="0 0 1"/>
    </joint>
  </xacro:macro>

  <xacro:property name="pi" value="3.14159265"/>
  <xacro:wheel name="left"  x_reflect="0"  y_reflect="1"/>
  <xacro:wheel name="right" x_reflect="0"  y_reflect="-1"/>

  <!-- ── Caster (front) ── -->
  <link name="caster_link">
    <visual>
      <geometry><sphere radius="0.04"/></geometry>
      <material name="gray"/>
    </visual>
    <collision>
      <geometry><sphere radius="0.04"/></geometry>
    </collision>
    <inertial>
      <mass value="0.1"/>
      <inertia ixx="0.0001" ixy="0" ixz="0" iyy="0.0001" iyz="0" izz="0.0001"/>
    </inertial>
  </link>
  <joint name="caster_joint" type="fixed">
    <parent link="base_link"/>
    <child link="caster_link"/>
    <origin xyz="0.15 0 -0.06"/>
  </joint>

  <!-- ── LiDAR link ── -->
  <link name="lidar_link">
    <visual>
      <geometry><cylinder radius="0.04" length="0.05"/></geometry>
      <material name="gray"/>
    </visual>
    <collision>
      <geometry><cylinder radius="0.04" length="0.05"/></geometry>
    </collision>
    <inertial>
      <mass value="0.2"/>
      <inertia ixx="0.0001" ixy="0" ixz="0" iyy="0.0001" iyz="0" izz="0.0001"/>
    </inertial>
  </link>
  <joint name="lidar_joint" type="fixed">
    <parent link="base_link"/>
    <child link="lidar_link"/>
    <origin xyz="0.1 0 0.1"/>
  </joint>

  <!-- ── Gazebo plugins ── -->
  <gazebo>
    <plugin filename="gz-sim-diff-drive-system"
            name="gz::sim::systems::DiffDrive">
      <left_joint>left_wheel_joint</left_joint>
      <right_joint>right_wheel_joint</right_joint>
      <wheel_separation>0.34</wheel_separation>
      <wheel_radius>0.08</wheel_radius>
      <odom_publish_frequency>50</odom_publish_frequency>
      <topic>cmd_vel</topic>
      <odom_topic>odom</odom_topic>
      <frame_id>odom</frame_id>
      <child_frame_id>base_link</child_frame_id>
      <max_linear_velocity>3.0</max_linear_velocity>
      <max_angular_velocity>3.0</max_angular_velocity>
      <max_linear_acceleration>2.0</max_linear_acceleration>
    </plugin>

    <plugin filename="gz-sim-joint-state-publisher-system"
            name="gz::sim::systems::JointStatePublisher">
      <joint_name>left_wheel_joint</joint_name>
      <joint_name>right_wheel_joint</joint_name>
    </plugin>
  </gazebo>

  <!-- ── 2D LiDAR sensor ── -->
  <gazebo reference="lidar_link">
    <sensor name="lidar" type="gpu_lidar">
      <topic>scan</topic>
      <update_rate>10</update_rate>
      <lidar>
        <scan>
          <horizontal>
            <samples>360</samples>
            <resolution>1</resolution>
            <min_angle>-3.14159</min_angle>
            <max_angle>3.14159</max_angle>
          </horizontal>
        </scan>
        <range>
          <min>0.12</min>
          <max>10.0</max>
          <resolution>0.01</resolution>
        </range>
        <noise>
          <type>gaussian</type>
          <mean>0.0</mean>
          <stddev>0.01</stddev>
        </noise>
      </lidar>
      <always_on>true</always_on>
      <visualize>true</visualize>
    </sensor>
  </gazebo>

</robot>